terminate called after throwing an instance of 'std::runtime_error'
  what():  /cfs/klemming/home/p/pennati/ParallelPoissonSolver/solverPoissonMPI_alpaka/thirdParty/alpaka/include/alpaka/platform/PlatformUniformCudaHipRt.hpp(131) 'rc' A previous API call (not this one) set the error  : 'hipErrorOutOfMemory': 'out of memory'!
srun: error: nid002794: task 0: Aborted
srun: Terminating StepId=7394473.0
slurmstepd: error: *** STEP 7394473.0 ON nid002794 CANCELLED AT 2025-01-15T16:56:53 ***
srun: error: nid002794: tasks 1-7: Terminated
srun: Force Terminated StepId=7394473.0
